[2024-09-24T22:17:24.107+0000] {local_task_job_runner.py:120} INFO - ::group::Pre task execution logs
[2024-09-24T22:17:24.288+0000] {taskinstance.py:2076} INFO - Dependencies all met for dep_context=non-requeueable deps ti=<TaskInstance: dados_climaticos.extrai_dados_climaticos scheduled__2024-08-26T00:00:00+00:00 [queued]>
[2024-09-24T22:17:24.391+0000] {taskinstance.py:2076} INFO - Dependencies all met for dep_context=requeueable deps ti=<TaskInstance: dados_climaticos.extrai_dados_climaticos scheduled__2024-08-26T00:00:00+00:00 [queued]>
[2024-09-24T22:17:24.396+0000] {taskinstance.py:2306} INFO - Starting attempt 1 of 1
[2024-09-24T22:17:24.506+0000] {taskinstance.py:2330} INFO - Executing <Task(PythonOperator): extrai_dados_climaticos> on 2024-08-26 00:00:00+00:00
[2024-09-24T22:17:24.565+0000] {warnings.py:112} WARNING - /home/***/.local/lib/python3.12/site-packages/***/task/task_runner/standard_task_runner.py:62: DeprecationWarning: This process (pid=1019) is multi-threaded, use of fork() may lead to deadlocks in the child.
  pid = os.fork()

[2024-09-24T22:17:24.575+0000] {standard_task_runner.py:64} INFO - Started process 1028 to run task
[2024-09-24T22:17:24.587+0000] {standard_task_runner.py:90} INFO - Running: ['***', 'tasks', 'run', 'dados_climaticos', 'extrai_dados_climaticos', 'scheduled__2024-08-26T00:00:00+00:00', '--job-id', '178', '--raw', '--subdir', 'DAGS_FOLDER/dados_climaticos.py', '--cfg-path', '/tmp/tmpysi9i7kh']
[2024-09-24T22:17:24.616+0000] {standard_task_runner.py:91} INFO - Job 178: Subtask extrai_dados_climaticos
[2024-09-24T22:17:24.989+0000] {task_command.py:426} INFO - Running <TaskInstance: dados_climaticos.extrai_dados_climaticos scheduled__2024-08-26T00:00:00+00:00 [running]> on host 9ad8820f2601
[2024-09-24T22:17:25.667+0000] {taskinstance.py:2648} INFO - Exporting env vars: AIRFLOW_CTX_DAG_OWNER='***' AIRFLOW_CTX_DAG_ID='dados_climaticos' AIRFLOW_CTX_TASK_ID='extrai_dados_climaticos' AIRFLOW_CTX_EXECUTION_DATE='2024-08-26T00:00:00+00:00' AIRFLOW_CTX_TRY_NUMBER='1' AIRFLOW_CTX_DAG_RUN_ID='scheduled__2024-08-26T00:00:00+00:00'
[2024-09-24T22:17:25.682+0000] {taskinstance.py:430} INFO - ::endgroup::
[2024-09-24T22:17:25.691+0000] {taskinstance.py:441} INFO - ::group::Post task execution logs
[2024-09-24T22:17:25.694+0000] {taskinstance.py:2905} ERROR - Task failed with exception
Traceback (most recent call last):
  File "/home/airflow/.local/lib/python3.12/site-packages/airflow/models/taskinstance.py", line 465, in _execute_task
    result = _execute_callable(context=context, **execute_callable_kwargs)
             ^^^^^^^^^^^^^^^^^^^^^^^^^^^^^^^^^^^^^^^^^^^^^^^^^^^^^^^^^^^^^
  File "/home/airflow/.local/lib/python3.12/site-packages/airflow/models/taskinstance.py", line 432, in _execute_callable
    return execute_callable(context=context, **execute_callable_kwargs)
           ^^^^^^^^^^^^^^^^^^^^^^^^^^^^^^^^^^^^^^^^^^^^^^^^^^^^^^^^^^^^
  File "/home/airflow/.local/lib/python3.12/site-packages/airflow/models/baseoperator.py", line 401, in wrapper
    return func(self, *args, **kwargs)
           ^^^^^^^^^^^^^^^^^^^^^^^^^^^
  File "/home/airflow/.local/lib/python3.12/site-packages/airflow/operators/python.py", line 235, in execute
    return_value = self.execute_callable()
                   ^^^^^^^^^^^^^^^^^^^^^^^
  File "/home/airflow/.local/lib/python3.12/site-packages/airflow/operators/python.py", line 252, in execute_callable
    return self.python_callable(*self.op_args, **self.op_kwargs)
           ^^^^^^^^^^^^^^^^^^^^^^^^^^^^^^^^^^^^^^^^^^^^^^^^^^^^^
  File "/opt/airflow/dags/dados_climaticos.py", line 28, in extrai_dados
    f'{city}/{data_interval_end}/{ds_add(data_interval_end,7)}?unitGroup=metric&include=days&key={key}&contentType=csv')
                                  ^^^^^^^^^^^^^^^^^^^^^^^^^^^
  File "/home/airflow/.local/lib/python3.12/site-packages/airflow/macros/__init__.py", line 59, in ds_add
    dt = datetime.strptime(str(ds), "%Y-%m-%d") + timedelta(days=days)
         ^^^^^^^^^^^^^^^^^^^^^^^^^^^^^^^^^^^^^^
  File "/usr/local/lib/python3.12/_strptime.py", line 554, in _strptime_datetime
    tt, fraction, gmtoff_fraction = _strptime(data_string, format)
                                    ^^^^^^^^^^^^^^^^^^^^^^^^^^^^^^
  File "/usr/local/lib/python3.12/_strptime.py", line 336, in _strptime
    raise ValueError("unconverted data remains: %s" %
ValueError: unconverted data remains:  00:00:00+00:00
[2024-09-24T22:17:25.762+0000] {taskinstance.py:1206} INFO - Marking task as FAILED. dag_id=dados_climaticos, task_id=extrai_dados_climaticos, run_id=scheduled__2024-08-26T00:00:00+00:00, execution_date=20240826T000000, start_date=20240924T221724, end_date=20240924T221725
[2024-09-24T22:17:25.881+0000] {standard_task_runner.py:110} ERROR - Failed to execute job 178 for task extrai_dados_climaticos (unconverted data remains:  00:00:00+00:00; 1028)
[2024-09-24T22:17:25.982+0000] {local_task_job_runner.py:243} INFO - Task exited with return code 1
[2024-09-24T22:17:26.084+0000] {taskinstance.py:3503} INFO - 0 downstream tasks scheduled from follow-on schedule check
[2024-09-24T22:17:26.091+0000] {local_task_job_runner.py:222} INFO - ::endgroup::
