[2024-09-24T20:45:45.715+0000] {local_task_job_runner.py:120} INFO - ::group::Pre task execution logs
[2024-09-24T20:45:45.812+0000] {taskinstance.py:2076} INFO - Dependencies all met for dep_context=non-requeueable deps ti=<TaskInstance: meu_primeiro_dag.cria_pasta manual__2024-09-24T20:45:41.314310+00:00 [queued]>
[2024-09-24T20:45:45.843+0000] {taskinstance.py:2076} INFO - Dependencies all met for dep_context=requeueable deps ti=<TaskInstance: meu_primeiro_dag.cria_pasta manual__2024-09-24T20:45:41.314310+00:00 [queued]>
[2024-09-24T20:45:45.844+0000] {taskinstance.py:2306} INFO - Starting attempt 1 of 1
[2024-09-24T20:45:45.903+0000] {taskinstance.py:2330} INFO - Executing <Task(BashOperator): cria_pasta> on 2024-09-24 20:45:41.314310+00:00
[2024-09-24T20:45:45.929+0000] {warnings.py:112} WARNING - /home/***/.local/lib/python3.12/site-packages/***/task/task_runner/standard_task_runner.py:62: DeprecationWarning: This process (pid=128) is multi-threaded, use of fork() may lead to deadlocks in the child.
  pid = os.fork()

[2024-09-24T20:45:45.934+0000] {standard_task_runner.py:64} INFO - Started process 130 to run task
[2024-09-24T20:45:45.934+0000] {standard_task_runner.py:90} INFO - Running: ['***', 'tasks', 'run', 'meu_primeiro_dag', 'cria_pasta', 'manual__2024-09-24T20:45:41.314310+00:00', '--job-id', '166', '--raw', '--subdir', 'DAGS_FOLDER/meu_primeiro_dag.py', '--cfg-path', '/tmp/tmpq4hz6u3w']
[2024-09-24T20:45:45.943+0000] {standard_task_runner.py:91} INFO - Job 166: Subtask cria_pasta
[2024-09-24T20:45:46.108+0000] {task_command.py:426} INFO - Running <TaskInstance: meu_primeiro_dag.cria_pasta manual__2024-09-24T20:45:41.314310+00:00 [running]> on host 728271395ced
[2024-09-24T20:45:46.464+0000] {taskinstance.py:2648} INFO - Exporting env vars: AIRFLOW_CTX_DAG_OWNER='***' AIRFLOW_CTX_DAG_ID='meu_primeiro_dag' AIRFLOW_CTX_TASK_ID='cria_pasta' AIRFLOW_CTX_EXECUTION_DATE='2024-09-24T20:45:41.314310+00:00' AIRFLOW_CTX_TRY_NUMBER='1' AIRFLOW_CTX_DAG_RUN_ID='manual__2024-09-24T20:45:41.314310+00:00'
[2024-09-24T20:45:46.466+0000] {taskinstance.py:430} INFO - ::endgroup::
[2024-09-24T20:45:46.468+0000] {subprocess.py:63} INFO - Tmp dir root location: /tmp
[2024-09-24T20:45:46.470+0000] {subprocess.py:75} INFO - Running command: ['/usr/bin/bash', '-c', ' cat "/home/paulovictor/workspace/***-workspace/Airflow/pass.txt" | sudo -S mkdir -p "/home/paulovictor/workspace/***-workspace/Airflow/pasta=2024-09-24 00:00:00+00:00/" ']
[2024-09-24T20:45:46.493+0000] {subprocess.py:86} INFO - Output:
[2024-09-24T20:45:46.498+0000] {subprocess.py:93} INFO - cat: /home/paulovictor/workspace/***-workspace/Airflow/pass.txt: No such file or directory
[2024-09-24T20:45:46.576+0000] {subprocess.py:93} INFO - [sudo] password for default:
[2024-09-24T20:45:46.576+0000] {subprocess.py:93} INFO - sudo: no password was provided
[2024-09-24T20:45:46.577+0000] {subprocess.py:93} INFO - sudo: a password is required
[2024-09-24T20:45:46.577+0000] {subprocess.py:97} INFO - Command exited with return code 1
[2024-09-24T20:45:46.578+0000] {taskinstance.py:441} INFO - ::group::Post task execution logs
[2024-09-24T20:45:46.594+0000] {taskinstance.py:2905} ERROR - Task failed with exception
Traceback (most recent call last):
  File "/home/airflow/.local/lib/python3.12/site-packages/airflow/models/taskinstance.py", line 465, in _execute_task
    result = _execute_callable(context=context, **execute_callable_kwargs)
             ^^^^^^^^^^^^^^^^^^^^^^^^^^^^^^^^^^^^^^^^^^^^^^^^^^^^^^^^^^^^^
  File "/home/airflow/.local/lib/python3.12/site-packages/airflow/models/taskinstance.py", line 432, in _execute_callable
    return execute_callable(context=context, **execute_callable_kwargs)
           ^^^^^^^^^^^^^^^^^^^^^^^^^^^^^^^^^^^^^^^^^^^^^^^^^^^^^^^^^^^^
  File "/home/airflow/.local/lib/python3.12/site-packages/airflow/models/baseoperator.py", line 401, in wrapper
    return func(self, *args, **kwargs)
           ^^^^^^^^^^^^^^^^^^^^^^^^^^^
  File "/home/airflow/.local/lib/python3.12/site-packages/airflow/operators/bash.py", line 243, in execute
    raise AirflowException(
airflow.exceptions.AirflowException: Bash command failed. The command returned a non-zero exit code 1.
[2024-09-24T20:45:46.606+0000] {taskinstance.py:1206} INFO - Marking task as FAILED. dag_id=meu_primeiro_dag, task_id=cria_pasta, run_id=manual__2024-09-24T20:45:41.314310+00:00, execution_date=20240924T204541, start_date=20240924T204545, end_date=20240924T204546
[2024-09-24T20:45:46.632+0000] {standard_task_runner.py:110} ERROR - Failed to execute job 166 for task cria_pasta (Bash command failed. The command returned a non-zero exit code 1.; 130)
[2024-09-24T20:45:46.677+0000] {local_task_job_runner.py:243} INFO - Task exited with return code 1
[2024-09-24T20:45:46.720+0000] {taskinstance.py:3503} INFO - 0 downstream tasks scheduled from follow-on schedule check
[2024-09-24T20:45:46.724+0000] {local_task_job_runner.py:222} INFO - ::endgroup::
